<?xml version="1.0" ?>
<robot name="moiro_arm" xmlns:xacro="http://www.ros.org/wiki/xacro">

<xacro:include filename="$(find mycobot_description)/obj/xacro/materials.xacro"/>




	<link name="world"/>

	<xacro:property name="effort" value="5.0"/>
	<xacro:property name="velocity" value="2.792527"/>




	<link name="base">

		<inertial>
			<origin xyz="0 0 0.0" rpy="0 0 0"/>
			<mass value="0.33"/>
			<inertia
				ixx="0.000784" ixy="0.0" ixz="0.0"
				iyy="0.000867" iyz="0.0"
				izz="0.001598"/>
		</inertial>

		<visual>
			<geometry>
				<mesh filename="file://$(find mycobot_description)/obj/mesh/base.dae"/>
			</geometry>
			<material name="silver"/>
			<origin xyz = "0.0 0 0 " rpy = "0 0 ${pi/2}"/>
		</visual>

		<collision>
			<origin xyz = "0.0 0 0 " rpy = " 0 0 ${pi/2}"/>
			<geometry>
				<cylinder length="0.102" radius="0.0725"/>
			</geometry>
		</collision>

	</link>

	




	<link name="link1">

		<inertial>
			<origin xyz="0 0 0.0" rpy="0 0 0"/>
			<mass value="0.12"/>
			<inertia
				ixx="0.000148" ixy="0.0" ixz="0.0"
				iyy="0.000148" iyz="0.0"
				izz="0.000096"/>
		</inertial>

		<visual>
			<geometry>
				<mesh filename="file://$(find mycobot_description)/obj/mesh/link1.dae"/>
			</geometry>
			<origin xyz = "0.0 0 -0.078 " rpy = " 0 0 ${pi/2}"/>
		</visual>

		<collision>
			<origin xyz = "0.0 0 -0.078 " rpy = " 0 0 ${pi/2}"/>
			<geometry>
				<cylinder length="0.106" radius="0.043"/>
			</geometry>
		</collision>

	</link>
	



	<link name="link2">

		<inertial>
			<origin xyz="0 0 0.0" rpy="0 0 0"/>
			<mass value="0.19"/>
			<inertia
				ixx="0.000148" ixy="0.0" ixz="0.0"
				iyy="0.000148" iyz="0.0"
				izz="0.000096"/>
		</inertial>

		<visual>
			<geometry>
				<mesh filename="file://$(find mycobot_description)/obj/mesh/link2.dae"/>
			</geometry>
			<origin xyz = "0.0 0 -0.04 " rpy = " 0 ${pi/2} 0"/>
		</visual>

		<collision>
			<origin xyz = "0.0 0 -0.04 " rpy = " 0 ${pi/2} 0"/>
			<geometry>
				<cylinder length="0.18" radius="0.036"/>
			</geometry>
		</collision>

	</link>




	<link name="link3">
	
		<inertial>
			<origin xyz="0 0 0.0" rpy="0 0 0"/>
		  	<mass value="0.16"/>
			<inertia
			  ixx="0.000148" ixy="0.0" ixz="0.0"
			  iyy="0.000148" iyz="0.0"
			  izz="0.000096"/>
		</inertial>

		<visual>
		  	<geometry>
		   		<mesh filename="file://$(find mycobot_description)/obj/mesh/link3.dae"/>
		  	</geometry>
			<origin xyz = "0.0 0 0.039 " rpy = " ${pi/2} ${pi/2} ${pi/2}"/>
		</visual>

		<collision>
			<origin xyz = "0.0 0 0.039 " rpy = " ${pi/2} ${pi/2} ${pi/2}"/>
		  	<geometry>
		   		<cylinder length="0.14" radius="0.0305"/>
		  	</geometry>	  	
		</collision>

	</link>

	<link name="link4">

		<inertial>
		  	<origin xyz="0 0 0.0" rpy="0 0 0"/>
			<mass value="0.124"/>
			<inertia
			  	ixx="0.000103" ixy="0.0" ixz="0.0"
			  	iyy="0.000103" iyz="0.0"
			  	izz="0.000096"/>
		</inertial>

		<visual>
			<geometry>
				<mesh filename="file://$(find mycobot_description)/obj/mesh/link4.dae"/>
			</geometry>
			<origin xyz = "0.0 -0.0024 -0.05 " rpy = "${pi/2} ${pi/2} 0 "/>
		</visual>

		<collision>
			<origin xyz = "0.0 -0.0024 -0.05 " rpy = "${pi/2} ${pi/2} 0 "/>
			<geometry>
				<cylinder length="0.083" radius="0.029"/>
			</geometry>
		</collision>

	</link>

	<link name="link5">
		<inertial>
			<origin xyz="0 0 0.0" rpy="0 0 0"/>
		  	<mass value="0.11"/>
			<inertia
			  ixx="0.000103" ixy="0.0" ixz="0.0"
			  iyy="0.000103" iyz="0.0"
			  izz="0.000096"/>
		</inertial>

		<visual>
		  	<geometry>
				<mesh filename="file://$(find mycobot_description)/obj/mesh/link5.dae"/>
		  	</geometry>
		  	<origin xyz = "0.0 0 -0.05 " rpy = "0 0 ${-pi/2}"/>
		</visual>

		<collision>
		  	<origin xyz = "0.0 0 -0.05 " rpy = "0 0 ${-pi/2}"/>
		   	<geometry>	
		   		<cylinder length="0.0849" radius="0.029"/>
		  	</geometry>
		</collision>

	</link>

	<link name="link6">

		<inertial>
			<origin xyz="0 0 0.0" rpy="0 0 0"/>
		  	<mass value="0.0739"/>
			<inertia
			  ixx="0.00006649" ixy="0.0" ixz="0.0"
			  iyy="0.00006649" iyz="0.0"
			  izz="0.000096"/>
		</inertial>

		<visual>
			<geometry>
				<mesh filename="file://$(find mycobot_description)/obj/mesh/link6.dae"/>
			</geometry>
			<material name = "grey">
				<color rgba = "0.5 0.5 0.5 1"/>
			</material>
				<origin xyz = "0.0 0.0 -0.022 " rpy = " ${pi/2} ${pi/2} 0"/>
		</visual>

		<collision>
		  	<origin xyz = "0.0 0.0 -0.022 " rpy = " ${pi/2} ${pi/2} 0"/>
		   	<geometry>	
		   		<cylinder length="0.0225" radius="0.026"/>
		  	</geometry>
		</collision>

	</link>


	<joint name="virtual_joint" type="fixed">
		<parent link="world"/>
		<child link="base"/>
		<origin xyz= "0 0 0" rpy = "0 0 0"/>  
	</joint>
	

	<joint name="joint2_to_joint1" type="revolute">
		<axis xyz="0 0 1"/>
		<limit effort = "${effort}" lower = "-2.96" upper = "2.96" velocity = "${velocity}"/>
		<parent link="base"/>
		<child link="link1"/>
		<origin xyz= "0 0 0.173" rpy = "0 0 0"/>  
        <dynamics damping="12.0" friction="6.0"/>
	</joint>

	<joint name="joint3_to_joint2" type="revolute">
		<axis xyz="0 0 1"/>
		<limit effort = "${effort}" lower = "-2.79" upper = "2.79" velocity = "${velocity}"/>
		<parent link="link1"/>
		<child link="link2"/>
		<origin xyz= "0 -0.086 0" rpy = "0 -1.57080  1.57080"/>  
        <dynamics damping="12.0" friction="6.0"/>
	</joint>

	<joint name="joint4_to_joint3" type="revolute">
		<axis xyz=" 0 0 1"/>
		<limit effort = "${effort}" lower = "-2.79" upper = "2.79" velocity = "${velocity}"/>
		<parent link="link2"/>
		<child link="link3"/>
		<origin xyz= "0.13635 0 -0.086   " rpy = "0 0 0"/>
        <dynamics damping="12.0" friction="6.0"/>
	</joint>

	<joint name="joint5_to_joint4" type="revolute">
		<axis xyz=" 0 0 1"/>
		<limit effort = "${effort}" lower = "-2.79" upper = "2.79" velocity = "${velocity}"/>
		<parent link="link3"/>
		<child link="link4"/>
    	<origin xyz= "0.1195 0  0.082" rpy = "0 0 1.57080"/>
        <dynamics damping="12.0" friction="6.0"/>
	</joint>

	<joint name="joint6_to_joint5" type="revolute">
		<axis xyz=" 0 0 1"/>
		<limit effort = "${effort}" lower = "-2.96" upper = "2.96" velocity = "${velocity}"/>
		<parent link="link4"/>
		<child link="link5"/>
    	<origin xyz= "0 -0.09415 0" rpy = "1.57080 0 0"/>
        <dynamics damping="7.0" friction="4.0"/>
	</joint>

	<joint name="joint6output_to_joint6" type="revolute">
		<axis xyz=" 0 0 1"/>
		<limit effort = "${effort}" lower = "-3.05" upper = "3.05" velocity = "${velocity}"/>
		<parent link="link5"/>
		<child link="link6"/>
    	<origin xyz= "0 0.055 0" rpy = "-1.57080 0 0 "/>
        <dynamics damping="3.0" friction="3.0"/>
	</joint>






    <gazebo>
        <plugin filename="ignition-gazebo-joint-state-publisher-system" name="ignition::gazebo::systems::JointStatePublisher">
            <topic>joint_states</topic>
        </plugin>    
    </gazebo>      

    <gazebo>
        <plugin filename="ignition-gazebo-joint-position-controller-system" name="ignition::gazebo::systems::JointPositionController">
            <joint_name>joint2_to_joint1</joint_name>
        </plugin>    
    </gazebo>  
    <gazebo>
        <plugin filename="ignition-gazebo-joint-position-controller-system" name="ignition::gazebo::systems::JointPositionController">
            <joint_name>joint3_to_joint2</joint_name>
        </plugin>    
    </gazebo>  
    <gazebo>
        <plugin filename="ignition-gazebo-joint-position-controller-system" name="ignition::gazebo::systems::JointPositionController">
            <joint_name>joint4_to_joint3</joint_name>
        </plugin>    
    </gazebo>  
    <gazebo>
        <plugin filename="ignition-gazebo-joint-position-controller-system" name="ignition::gazebo::systems::JointPositionController">
            <joint_name>joint5_to_joint4</joint_name>
        </plugin>    
    </gazebo>  
    <gazebo>
        <plugin filename="ignition-gazebo-joint-position-controller-system" name="ignition::gazebo::systems::JointPositionController">
            <joint_name>joint6_to_joint5</joint_name>
        </plugin>    
    </gazebo>  
    <gazebo>
        <plugin filename="ignition-gazebo-joint-position-controller-system" name="ignition::gazebo::systems::JointPositionController">
            <joint_name>joint6output_to_joint6</joint_name>
        </plugin>    
    </gazebo>  

</robot>
