<sdf version='1.7'>
  <model name='firefighter'>
    <link name='base'>
      <inertial>
        <pose>0 0 0 0 -0 0</pose>
        <mass>1</mass>
        <inertia>
          <ixx>1</ixx>
          <ixy>0</ixy>
          <ixz>0</ixz>
          <iyy>1</iyy>
          <iyz>0</iyz>
          <izz>1</izz>
        </inertia>
      </inertial>
      <collision name='base_collision'>
        <pose>0 0 0 0 -0 3.14159</pose>
        <geometry>
          <mesh>
            <scale>1 1 1</scale>
            <uri>model://mycobot_description/urdf/mycobot_320_pi_2022/base.dae</uri>
          </mesh>
        </geometry>
      </collision>
      <visual name='base_visual'>
        <pose>0 0 0 0 -0 3.14159</pose>
        <geometry>
          <mesh>
            <scale>1 1 1</scale>
            <uri>model://mycobot_description/urdf/mycobot_320_pi_2022/base.dae</uri>
          </mesh>
        </geometry>
      </visual>
    </link>
    <joint name='joint2_to_joint1' type='revolute'>
      <pose relative_to='base'>0 0 0.162 0 -0 0</pose>
      <parent>base</parent>
      <child>link1</child>
      <axis>
        <xyz>0 0 1</xyz>
        <limit>
          <lower>-2.96</lower>
          <upper>2.96</upper>
          <effort>1000</effort>
          <velocity>0</velocity>
        </limit>
        <dynamics>
          <spring_reference>0</spring_reference>
          <spring_stiffness>0</spring_stiffness>
        </dynamics>
      </axis>
    </joint>
    <link name='link1'>
      <pose relative_to='joint2_to_joint1'>0 0 0 0 -0 0</pose>
      <inertial>
        <pose>0 0 0 0 -0 0</pose>
        <mass>1</mass>
        <inertia>
          <ixx>1</ixx>
          <ixy>0</ixy>
          <ixz>0</ixz>
          <iyy>1</iyy>
          <iyz>0</iyz>
          <izz>1</izz>
        </inertia>
      </inertial>
      <collision name='link1_collision'>
        <pose>0.115 -0.172 -0.09 0 -0 3.14159</pose>
        <geometry>
          <mesh>
            <scale>1 1 1</scale>
            <uri>model://mycobot_description/urdf/mycobot_320_pi_2022/link1.dae</uri>
          </mesh>
        </geometry>
      </collision>
      <visual name='link1_visual'>
        <pose>0.115 -0.172 -0.086 0 -0 3.14159</pose>
        <geometry>
          <mesh>
            <scale>1 1 1</scale>
            <uri>model://mycobot_description/urdf/mycobot_320_pi_2022/link1.dae</uri>
          </mesh>
        </geometry>
      </visual>
    </link>
    <joint name='joint3_to_joint2' type='revolute'>
      <pose relative_to='link1'>0 0 0 -3.14159 -1.57079 -1.57079</pose>
      <parent>link1</parent>
      <child>link2</child>
      <axis>
        <xyz>0 0 1</xyz>
        <limit>
          <lower>-2.79</lower>
          <upper>2.79</upper>
          <effort>1000</effort>
          <velocity>0</velocity>
        </limit>
        <dynamics>
          <spring_reference>0</spring_reference>
          <spring_stiffness>0</spring_stiffness>
        </dynamics>
      </axis>
    </joint>
    <link name='link2'>
      <pose relative_to='joint3_to_joint2'>0 0 0 0 -0 0</pose>
      <inertial>
        <pose>0 0 0 0 -0 0</pose>
        <mass>1</mass>
        <inertia>
          <ixx>1</ixx>
          <ixy>0</ixy>
          <ixz>0</ixz>
          <iyy>1</iyy>
          <iyz>0</iyz>
          <izz>1</izz>
        </inertia>
      </inertial>
      <collision name='link2_collision'>
        <pose>-0.075 -0.115 -0.022 1.5708 -0 1.5708</pose>
        <geometry>
          <mesh>
            <scale>1 1 1</scale>
            <uri>model://mycobot_description/urdf/mycobot_320_pi_2022/link2.dae</uri>
          </mesh>
        </geometry>
      </collision>
      <visual name='link2_visual'>
        <pose>-0.075 -0.115 -0.022 1.5708 -0 1.5708</pose>
        <geometry>
          <mesh>
            <scale>1 1 1</scale>
            <uri>model://mycobot_description/urdf/mycobot_320_pi_2022/link2.dae</uri>
          </mesh>
        </geometry>
      </visual>
    </link>
    <joint name='joint4_to_joint3' type='revolute'>
      <pose relative_to='link2'>0.13635 0 0 0 -0 0</pose>
      <parent>link2</parent>
      <child>link3</child>
      <axis>
        <xyz>0 0 1</xyz>
        <limit>
          <lower>-2.79</lower>
          <upper>2.79</upper>
          <effort>1000</effort>
          <velocity>0</velocity>
        </limit>
        <dynamics>
          <spring_reference>0</spring_reference>
          <spring_stiffness>0</spring_stiffness>
        </dynamics>
      </axis>
    </joint>
    <link name='link3'>
      <pose relative_to='joint4_to_joint3'>0 0 0 0 -0 0</pose>
      <inertial>
        <pose>0 0 0 0 -0 0</pose>
        <mass>1</mass>
        <inertia>
          <ixx>1</ixx>
          <ixy>0</ixy>
          <ixz>0</ixz>
          <iyy>1</iyy>
          <iyz>0</iyz>
          <izz>1</izz>
        </inertia>
      </inertial>
      <collision name='link3_collision'>
        <pose>-0.22 -0.115 0.142 1.5708 -0 1.5708</pose>
        <geometry>
          <mesh>
            <scale>1 1 1</scale>
            <uri>model://mycobot_description/urdf/mycobot_320_pi_2022/link3.dae</uri>
          </mesh>
        </geometry>
      </collision>
      <visual name='link3_visual'>
        <pose>-0.22 -0.115 0.142 1.5708 -0 1.5708</pose>
        <geometry>
          <mesh>
            <scale>1 1 1</scale>
            <uri>model://mycobot_description/urdf/mycobot_320_pi_2022/link3.dae</uri>
          </mesh>
        </geometry>
      </visual>
    </link>
    <joint name='joint5_to_joint4' type='revolute'>
      <pose relative_to='link3'>0.1205 0 0.082 0 -0 1.5708</pose>
      <parent>link3</parent>
      <child>link4</child>
      <axis>
        <xyz>0 0 1</xyz>
        <limit>
          <lower>-2.79</lower>
          <upper>2.79</upper>
          <effort>1000</effort>
          <velocity>0</velocity>
        </limit>
        <dynamics>
          <spring_reference>0</spring_reference>
          <spring_stiffness>0</spring_stiffness>
        </dynamics>
      </axis>
    </joint>
    <link name='link4'>
      <pose relative_to='joint5_to_joint4'>0 0 0 0 -0 0</pose>
      <inertial>
        <pose>0 0 0 0 -0 0</pose>
        <mass>1</mass>
        <inertia>
          <ixx>1</ixx>
          <ixy>0</ixy>
          <ixz>0</ixz>
          <iyy>1</iyy>
          <iyz>0</iyz>
          <izz>1</izz>
        </inertia>
      </inertial>
      <collision name='link4_collision'>
        <pose>-0.115 0.338 -0.1435 1.5708 -0 0</pose>
        <geometry>
          <mesh>
            <scale>1 1 1</scale>
            <uri>model://mycobot_description/urdf/mycobot_320_pi_2022/link4.dae</uri>
          </mesh>
        </geometry>
      </collision>
      <visual name='link4_visual'>
        <pose>-0.115 0.338 -0.1435 1.5708 -0 0</pose>
        <geometry>
          <mesh>
            <scale>1 1 1</scale>
            <uri>model://mycobot_description/urdf/mycobot_320_pi_2022/link4.dae</uri>
          </mesh>
        </geometry>
      </visual>
    </link>
    <joint name='joint6_to_joint5' type='revolute'>
      <pose relative_to='link4'>0 -0.084 0 1.5708 -0 0</pose>
      <parent>link4</parent>
      <child>link5</child>
      <axis>
        <xyz>0 0 1</xyz>
        <limit>
          <lower>-2.96</lower>
          <upper>2.96</upper>
          <effort>1000</effort>
          <velocity>0</velocity>
        </limit>
        <dynamics>
          <spring_reference>0</spring_reference>
          <spring_stiffness>0</spring_stiffness>
        </dynamics>
      </axis>
    </joint>
    <link name='link5'>
      <pose relative_to='joint6_to_joint5'>0 0 0 0 -0 0</pose>
      <inertial>
        <pose>0 0 0 0 -0 0</pose>
        <mass>1</mass>
        <inertia>
          <ixx>1</ixx>
          <ixy>0</ixy>
          <ixz>0</ixz>
          <iyy>1</iyy>
          <iyz>0</iyz>
          <izz>1</izz>
        </inertia>
      </inertial>
      <collision name='link5_collision'>
        <pose>-0.1149 -0.0322 -0.482 0 -0 0</pose>
        <geometry>
          <mesh>
            <scale>1 1 1</scale>
            <uri>model://mycobot_description/urdf/mycobot_320_pi_2022/link5.dae</uri>
          </mesh>
        </geometry>
      </collision>
      <visual name='link5_visual'>
        <pose>-0.1149 -0.0322 -0.482 0 -0 0</pose>
        <geometry>
          <mesh>
            <scale>1 1 1</scale>
            <uri>model://mycobot_description/urdf/mycobot_320_pi_2022/link5.dae</uri>
          </mesh>
        </geometry>
      </visual>
    </link>
    <joint name='joint6output_to_joint6' type='revolute'>
      <pose relative_to='link5'>0 0.06635 0 -1.5708 0 0</pose>
      <parent>link5</parent>
      <child>link6</child>
      <axis>
        <xyz>0 0 1</xyz>
        <limit>
          <lower>-3.05</lower>
          <upper>3.05</upper>
          <effort>1000</effort>
          <velocity>0</velocity>
        </limit>
        <dynamics>
          <spring_reference>0</spring_reference>
          <spring_stiffness>0</spring_stiffness>
        </dynamics>
      </axis>
    </joint>
    <link name='link6'>
      <pose relative_to='joint6output_to_joint6'>0 0 0 0 -0 0</pose>
      <inertial>
        <pose>0 0 0 0 -0 0</pose>
        <mass>1</mass>
        <inertia>
          <ixx>1</ixx>
          <ixy>0</ixy>
          <ixz>0</ixz>
          <iyy>1</iyy>
          <iyz>0</iyz>
          <izz>1</izz>
        </inertia>
      </inertial>
      <collision name='link6_collision'>
        <pose>-0.11478 0.433 -0.15 1.5708 -0 0</pose>
        <geometry>
          <mesh>
            <scale>1 1 1</scale>
            <uri>model://mycobot_description/urdf/mycobot_320_pi_2022/link6.dae</uri>
          </mesh>
        </geometry>
      </collision>
      <visual name='link6_visual'>
        <pose>-0.11478 0.433 -0.15 1.5708 -0 0</pose>
        <geometry>
          <mesh>
            <scale>1 1 1</scale>
            <uri>model://mycobot_description/urdf/mycobot_320_pi_2022/link6.dae</uri>
          </mesh>
        </geometry>
      </visual>
    </link>
  </model>
</sdf>
